Workbook

Sheet Hướng dẫn
B2: KẾ HOẠCH TEST PHÂN HỆ MUA HÀNG — ERP
B3: Dùng để giao việc test hằng ngày và báo cáo tiến độ. Lập ngày 26/10/2026.
B5: Thông số kế hoạch (ô vàng — sửa được)
B6: Ngày bắt đầu test | C6: 46322 | D6: Ngày đầu tiên tester bắt đầu. Đổi ô này thì cột "Ngày dự kiến" tự dời.
B7: Số giờ test thực mỗi ngày | C7: 6 | D7: Giả định: 8 giờ làm, ~2 giờ cho họp, ghi lỗi, chờ dựng bản. Đổi thì số ngày tự tính lại.
B8: Tỷ lệ test lại sau sửa lỗi | C8: 0.3 | D8: Giả định: khoảng 30% số giờ vòng 1 phải test lại sau khi dev sửa lỗi.
B11: Cách dùng hằng ngày
B12: 1. Sheet "Danh sách test" | C12: Lọc cột "Ngày dự kiến" = hôm nay → giao cho tester. Tester điền cột vàng: Người test, Ngày test, Trạng thái, Ghi chú lỗi.
B13: 2. Trạng thái | C13: Chưa test · Đang test · Đạt · Lỗi · Đã sửa – chờ test lại · Chờ người / dữ liệu. Chỉ chọn trong danh sách thả xuống.
B14: 3. Khi gặp lỗi | C14: Chọn "Lỗi", ghi ngắn: làm gì → thấy gì → đúng ra phải là gì (kèm ảnh chụp nếu được). Dev sửa xong đổi thành "Đã sửa – chờ test lại".
B15: 4. Sheet "25 tình huống" | C15: Trả lời câu hỏi "các case kế toán gửi đã ổn hết chưa": tự đếm theo các mục test của từng tình huống.
B16: 5. Sheet "Tiến độ" | C16: Số liệu để báo cáo: bao nhiêu mục đạt / lỗi / còn lại, ước tính số ngày còn lại. Tất cả tự tính, không cần sửa.
B17: 6. Sheet "Chờ đợi" | C17: Những mục chưa test được vì đang chờ người (kế toán mới) hoặc chờ dữ liệu / file thật. Tự lọc từ danh sách test.
B19: Ưu tiên | C19: P1 = bắt buộc trước khi đưa vào chi nhánh · P2 = nên có · P3 = làm khi có thời gian.
B20: Lưu ý | C20: 25 tình huống đã được kiểm tự động bằng máy (25/25 đạt ngày 26/10/2026). Kế hoạch này là kiểm bằng tay trên giao diện như người dùng thật — bước bắt buộc trước khi báo "ổn".
B21: Ước tính thời gian | C21: Giờ ở mỗi dòng là thời gian của 1 tester đã quen phần mềm, gồm cả chuẩn bị dữ liệu và ghi kết quả. Ngày đầu tiên thường chậm hơn (làm quen).

Sheet Danh sách test
A1: DANH SÁCH TEST — PHÂN HỆ MUA HÀNG
A2: Cột trắng: kế hoạch (dev điền). Cột vàng: tester điền. "Ngày thứ" và "Ngày dự kiến" tự tính theo giờ ước tính và thông số ở sheet Hướng dẫn; mục đang chờ không xếp ngày.
A4: Mã test | B4: Phần | C4: Màn | D4: Chức năng | E4: Cách test | F4: Kết quả đúng | G4: Tình huống liên quan | H4: Ưu tiên | I4: Giờ ước tính | J4: Phụ thuộc / đang chờ | K4: Đang chờ? | L4: Ngày thứ | M4: Ngày dự kiến | N4: Người test | O4: Ngày test thực tế | P4: Trạng thái | Q4: Ghi chú / mô tả lỗi | R4: khoá TH
A5: CH-01 | B5: Chung & đăng nhập | C5: ERP | D5: Đăng nhập & quyền | E5: Đăng nhập ERP bằng tài khoản website; mở phân hệ Mua hàng. Thử thêm 1 tài khoản không có quyền mua hàng. | F5: Vào được bằng tài khoản website, không phải đăng nhập lại; tài khoản không có quyền không thấy menu Mua hàng. | H5: P1 | I5: 0.5 | K5: Không | L5: =IF(K5="Có","Chờ",ROUNDUP(SUMIFS($I$5:I5,$K$5:K5,"Không")/'Hướng dẫn'!$C$7,0)) -> 1 | M5: =IF(ISNUMBER(L5),WORKDAY('Hướng dẫn'!$C$6,L5-1),"") -> 46322 | P5: Chưa test | Q5: Ví dụ ghi lỗi: Bấm Ghi phiếu → báo "lỗi máy chủ" → đúng ra phải lưu được. (Xoá câu này khi test thật) | S5: =IF(K5="Có",COUNTIF($K$5:K5,"Có"),"")
A6: CH-02 | B6: Chung & đăng nhập | C6: ERP | D6: Chi nhánh làm việc | E6: Đổi chi nhánh ở thanh dưới, mở lại các màn Mua hàng. | F6: Danh sách phiếu, tồn, hạn mức đổi theo chi nhánh đang chọn. | H6: P1 | I6: 0.5 | K6: Không | L6: =IF(K6="Có","Chờ",ROUNDUP(SUMIFS($I$5:I6,$K$5:K6,"Không")/'Hướng dẫn'!$C$7,0)) -> 1 | M6: =IF(ISNUMBER(L6),WORKDAY('Hướng dẫn'!$C$6,L6-1),"") -> 46322 | P6: Chưa test | S6: =IF(K6="Có",COUNTIF($K$5:K6,"Có"),"")
A7: CH-03 | B7: Chung & đăng nhập | C7: ERP | D7: Tìm kiếm menu | E7: Gõ tên màn hoặc mã (vd "MH03", "chứng từ") ở ô tìm kiếm menu. | F7: Ra đúng màn; không bật hộp đen / không tự điền mật khẩu. | H7: P3 | I7: 0.25 | K7: Không | L7: =IF(K7="Có","Chờ",ROUNDUP(SUMIFS($I$5:I7,$K$5:K7,"Không")/'Hướng dẫn'!$C$7,0)) -> 1 | M7: =IF(ISNUMBER(L7),WORKDAY('Hướng dẫn'!$C$6,L7-1),"") -> 46322 | P7: Chưa test | S7: =IF(K7="Có",COUNTIF($K$5:K7,"Có"),"")
A8: CH-04 | B8: Chung & đăng nhập | C8: ERP | D8: Cửa sổ xem / sửa | E8: Mở 1 phiếu, 1 NCC, 1 mặt hàng: thử bấm Sửa, Ghi, Thoát, nút ✕, phím Esc. | F8: Mở ra ở chế độ xem; bấm Sửa mới sửa được; ✕ và Esc đóng được cả khi đang xem. | H8: P2 | I8: 0.5 | K8: Không | L8: =IF(K8="Có","Chờ",ROUNDUP(SUMIFS($I$5:I8,$K$5:K8,"Không")/'Hướng dẫn'!$C$7,0)) -> 1 | M8: =IF(ISNUMBER(L8),WORKDAY('Hướng dẫn'!$C$6,L8-1),"") -> 46322 | P8: Chưa test | S8: =IF(K8="Có",COUNTIF($K$5:K8,"Có"),"")
A9: CH-05 | B9: Chung & đăng nhập | C9: ERP | D9: Nút Hướng dẫn | E9: Bấm nút Hướng dẫn trên từng màn MH00–MH14, DM10, DM11, DM15. | F9: Màn nào cũng có; nội dung nói đúng màn đó, đọc hiểu được. | H9: P2 | I9: 1 | K9: Không | L9: =IF(K9="Có","Chờ",ROUNDUP(SUMIFS($I$5:I9,$K$5:K9,"Không")/'Hướng dẫn'!$C$7,0)) -> 1 | M9: =IF(ISNUMBER(L9),WORKDAY('Hướng dẫn'!$C$6,L9-1),"") -> 46322 | P9: Chưa test | S9: =IF(K9="Có",COUNTIF($K$5:K9,"Có"),"")
A10: CH-06 | B10: Chung & đăng nhập | C10: ERP | D10: Bảng dữ liệu | E10: Kéo giãn cột, lọc, tìm trong bảng, sắp xếp ở danh sách chứng từ và danh mục. | F10: Kéo giãn được, mở lại vẫn nhớ độ rộng; lọc/tìm đúng. | H10: P3 | I10: 0.5 | K10: Không | L10: =IF(K10="Có","Chờ",ROUNDUP(SUMIFS($I$5:I10,$K$5:K10,"Không")/'Hướng dẫn'!$C$7,0)) -> 1 | M10: =IF(ISNUMBER(L10),WORKDAY('Hướng dẫn'!$C$6,L10-1),"") -> 46322 | P10: Chưa test | S10: =IF(K10="Có",COUNTIF($K$5:K10,"Có"),"")
A11: CH-07 | B11: Chung & đăng nhập | C11: MH00 | D11: Tổng quan & 25 tình huống | E11: Mở MH00, bấm lần lượt từng tình huống. | F11: Mỗi tình huống dẫn đúng tới màn / phiếu xử lý. | H11: P2 | I11: 0.75 | K11: Không | L11: =IF(K11="Có","Chờ",ROUNDUP(SUMIFS($I$5:I11,$K$5:K11,"Không")/'Hướng dẫn'!$C$7,0)) -> 1 | M11: =IF(ISNUMBER(L11),WORKDAY('Hướng dẫn'!$C$6,L11-1),"") -> 46322 | P11: Chưa test | S11: =IF(K11="Có",COUNTIF($K$5:K11,"Có"),"")
A12: CH-08 | B12: Chung & đăng nhập | C12: MH13 | D12: Cơ sở dữ liệu mua hàng | E12: Đọc trang luồng dữ liệu, so với cách làm thực tế khi test. | F12: Luồng đúng với phần mềm; dùng được khi trình bày. | H12: P3 | I12: 0.5 | K12: Không | L12: =IF(K12="Có","Chờ",ROUNDUP(SUMIFS($I$5:I12,$K$5:K12,"Không")/'Hướng dẫn'!$C$7,0)) -> 1 | M12: =IF(ISNUMBER(L12),WORKDAY('Hướng dẫn'!$C$6,L12-1),"") -> 46322 | P12: Chưa test | S12: =IF(K12="Có",COUNTIF($K$5:K12,"Có"),"")
A13: DM-01 | B13: Danh mục hàng & NCC | C13: DM11 | D13: Nhóm hàng ngành → nhãn → nhóm | E13: Thêm 1 ngành, 1 nhãn, 1 nhóm; thử mã đoạn sai độ dài, trùng mã; sửa; ngừng dùng. | F13: Đoạn mã đúng độ dài (2 / 3 / 1 ký tự), trùng bị chặn; có cột Cấp và "Đoạn mã trong mã hàng". | H13: P1 | I13: 1 | K13: Không | L13: =IF(K13="Có","Chờ",ROUNDUP(SUMIFS($I$5:I13,$K$5:K13,"Không")/'Hướng dẫn'!$C$7,0)) -> 1 | M13: =IF(ISNUMBER(L13),WORKDAY('Hướng dẫn'!$C$6,L13-1),"") -> 46322 | P13: Chưa test | S13: =IF(K13="Có",COUNTIF($K$5:K13,"Có"),"")
A14: DM-02 | B14: Danh mục hàng & NCC | C14: DM10 | D14: Sinh mã hàng tự động | E14: Thêm mặt hàng mới, chọn nhóm cấp 3. | F14: Mã 9 số = ngành + nhãn + nhóm + số thứ tự tiếp theo; không bị nhảy / trùng; giải thích từng đoạn mã. | H14: P1 | I14: 1 | K14: Không | L14: =IF(K14="Có","Chờ",ROUNDUP(SUMIFS($I$5:I14,$K$5:K14,"Không")/'Hướng dẫn'!$C$7,0)) -> 2 | M14: =IF(ISNUMBER(L14),WORKDAY('Hướng dẫn'!$C$6,L14-1),"") -> 46323 | P14: Chưa test | S14: =IF(K14="Có",COUNTIF($K$5:K14,"Có"),"")
A15: DM-03 | B15: Danh mục hàng & NCC | C15: DM10 | D15: Mã quà, mã đuôi, mã biến thể | E15: Tạo hàng quà (đầu Q); tạo mã có đuôi K / M / Q / T / Z; từ 1 mã gốc bấm "Tạo mã biến thể". | F15: Mã quà đúng quy tắc; đuôi đúng; biến thể mở mượt, giữ thông tin mã gốc. | H15: P2 | I15: 1 | K15: Không | L15: =IF(K15="Có","Chờ",ROUNDUP(SUMIFS($I$5:I15,$K$5:K15,"Không")/'Hướng dẫn'!$C$7,0)) -> 2 | M15: =IF(ISNUMBER(L15),WORKDAY('Hướng dẫn'!$C$6,L15-1),"") -> 46323 | P15: Chưa test | S15: =IF(K15="Có",COUNTIF($K$5:K15,"Có"),"")
A16: DM-04 | B16: Danh mục hàng & NCC | C16: DM10 | D16: Sửa mã, đổi nhóm | E16: Sửa tay mã hàng; đổi nhóm của hàng mới; nhập mã đã có. | F16: Sửa được; đổi nhóm thì gợi ý mã mới; mã trùng bị chặn. | H16: P2 | I16: 0.5 | K16: Không | L16: =IF(K16="Có","Chờ",ROUNDUP(SUMIFS($I$5:I16,$K$5:K16,"Không")/'Hướng dẫn'!$C$7,0)) -> 2 | M16: =IF(ISNUMBER(L16),WORKDAY('Hướng dẫn'!$C$6,L16-1),"") -> 46323 | P16: Chưa test | S16: =IF(K16="Có",COUNTIF($K$5:K16,"Có"),"")
A17: DM-05 | B17: Danh mục hàng & NCC | C17: DM10 | D17: Đơn vị tính & quy đổi | E17: Khai Lon (tỉ lệ 1), Thùng = 24 Lon; chọn ĐVT mua mặc định. | F17: ĐVT nhỏ nhất tỉ lệ 1; quy đổi dùng đúng ở phiếu, báo cáo, min–max. | G17: VD4 | H17: P1 | I17: 0.75 | K17: Không | L17: =IF(K17="Có","Chờ",ROUNDUP(SUMIFS($I$5:I17,$K$5:K17,"Không")/'Hướng dẫn'!$C$7,0)) -> 2 | M17: =IF(ISNUMBER(L17),WORKDAY('Hướng dẫn'!$C$6,L17-1),"") -> 46323 | P17: Chưa test | R17: |VD4| | S17: =IF(K17="Có",COUNTIF($K$5:K17,"Có"),"")
A18: DM-06 | B18: Danh mục hàng & NCC | C18: DM10 | D18: Thuế suất mặt hàng | E18: Khai hàng 8%, 10%, 0%; đưa vào phiếu nhập. | F18: Thuế suất hiện rõ; vào phiếu tự lấy đúng. | G18: VD2 | H18: P1 | I18: 0.5 | K18: Không | L18: =IF(K18="Có","Chờ",ROUNDUP(SUMIFS($I$5:I18,$K$5:K18,"Không")/'Hướng dẫn'!$C$7,0)) -> 2 | M18: =IF(ISNUMBER(L18),WORKDAY('Hướng dẫn'!$C$6,L18-1),"") -> 46323 | P18: Chưa test | R18: |VD2| | S18: =IF(K18="Có",COUNTIF($K$5:K18,"Có"),"")
A19: DM-07 | B19: Danh mục hàng & NCC | C19: DM10 | D19: Bảng giá mua theo NCC | E19: Khai giá cố định theo ĐVT (Hộp), có hiệu lực, gồm / chưa VAT; khai giá thứ 2 hết hiệu lực. | F19: Phiếu lấy đúng giá đang hiệu lực, quy đổi đúng ĐVT, đúng loại giá (gồm / chưa VAT). | G19: TH25, VD4 | H19: P1 | I19: 1 | K19: Không | L19: =IF(K19="Có","Chờ",ROUNDUP(SUMIFS($I$5:I19,$K$5:K19,"Không")/'Hướng dẫn'!$C$7,0)) -> 2 | M19: =IF(ISNUMBER(L19),WORKDAY('Hướng dẫn'!$C$6,L19-1),"") -> 46323 | P19: Chưa test | R19: |TH25|VD4| | S19: =IF(K19="Có",COUNTIF($K$5:K19,"Có"),"")
A20: DM-08 | B20: Danh mục hàng & NCC | C20: DM10 | D20: Tồn min–max | E20: Mở hộp Tồn min–max của 1 mã; nhập theo Thùng, đặt tròn theo Thùng. | F20: Câu ví dụ tự tính đúng; min ≥ max bị chặn; lưu đúng. | H20: P2 | I20: 0.75 | K20: Không | L20: =IF(K20="Có","Chờ",ROUNDUP(SUMIFS($I$5:I20,$K$5:K20,"Không")/'Hướng dẫn'!$C$7,0)) -> 2 | M20: =IF(ISNUMBER(L20),WORKDAY('Hướng dẫn'!$C$6,L20-1),"") -> 46323 | P20: Chưa test | S20: =IF(K20="Có",COUNTIF($K$5:K20,"Có"),"")
A21: DM-09 | B21: Danh mục hàng & NCC | C21: DM10 | D21: Nhập Excel mặt hàng | E21: Tải file mẫu, điền 20 mã (có vài dòng sai), nhập. | F21: Báo rõ dòng lỗi trước khi ghi; dòng đúng ghi được. | H21: P2 | I21: 1 | K21: Không | L21: =IF(K21="Có","Chờ",ROUNDUP(SUMIFS($I$5:I21,$K$5:K21,"Không")/'Hướng dẫn'!$C$7,0)) -> 2 | M21: =IF(ISNUMBER(L21),WORKDAY('Hướng dẫn'!$C$6,L21-1),"") -> 46323 | P21: Chưa test | S21: =IF(K21="Có",COUNTIF($K$5:K21,"Có"),"")
A22: DM-10 | B22: Danh mục hàng & NCC | C22: DM15 | D22: Danh mục đơn vị tính | E22: Thêm / sửa ĐVT; thêm "lon" khi đã có "Lon". | F22: Không trùng khác hoa thường; dùng được ngay ở mặt hàng. | H22: P3 | I22: 0.5 | K22: Không | L22: =IF(K22="Có","Chờ",ROUNDUP(SUMIFS($I$5:I22,$K$5:K22,"Không")/'Hướng dẫn'!$C$7,0)) -> 3 | M22: =IF(ISNUMBER(L22),WORKDAY('Hướng dẫn'!$C$6,L22-1),"") -> 46324 | P22: Chưa test | S22: =IF(K22="Có",COUNTIF($K$5:K22,"Có"),"")
A23: DM-11 | B23: Danh mục hàng & NCC | C23: MH01 | D23: Thêm nhà cung cấp | E23: Thêm NCC Trung Hậu đủ MST, địa chỉ, SĐT, nhóm NCC, hạn thanh toán, hạn mức. | F23: Lưu đủ; có Người tạo / Ngày giờ tạo; tìm được theo mã, tên, MST. | G23: TH1 | H23: P1 | I23: 1 | K23: Không | L23: =IF(K23="Có","Chờ",ROUNDUP(SUMIFS($I$5:I23,$K$5:K23,"Không")/'Hướng dẫn'!$C$7,0)) -> 3 | M23: =IF(ISNUMBER(L23),WORKDAY('Hướng dẫn'!$C$6,L23-1),"") -> 46324 | P23: Chưa test | R23: |TH1| | S23: =IF(K23="Có",COUNTIF($K$5:K23,"Có"),"")
A24: DM-12 | B24: Danh mục hàng & NCC | C24: MH01 | D24: NCC vừa là khách hàng | E24: Tích "Đối tượng này là: Khách hàng" cho 1 NCC. | F24: Cùng một mã hiện ở cả danh sách khách hàng và NCC; ô tích có giải thích dễ hiểu. | H24: P2 | I24: 0.5 | K24: Không | L24: =IF(K24="Có","Chờ",ROUNDUP(SUMIFS($I$5:I24,$K$5:K24,"Không")/'Hướng dẫn'!$C$7,0)) -> 3 | M24: =IF(ISNUMBER(L24),WORKDAY('Hướng dẫn'!$C$6,L24-1),"") -> 46324 | P24: Chưa test | S24: =IF(K24="Có",COUNTIF($K$5:K24,"Có"),"")
A25: DM-13 | B25: Danh mục hàng & NCC | C25: MH01 | D25: Nhãn hàng của NCC | E25: Mở tab nhãn hàng của NCC đã có phiếu. | F25: Chỉ đọc, tự lấy từ hàng trên phiếu (không phải khai tay). | H25: P3 | I25: 0.5 | K25: Không | L25: =IF(K25="Có","Chờ",ROUNDUP(SUMIFS($I$5:I25,$K$5:K25,"Không")/'Hướng dẫn'!$C$7,0)) -> 3 | M25: =IF(ISNUMBER(L25),WORKDAY('Hướng dẫn'!$C$6,L25-1),"") -> 46324 | P25: Chưa test | S25: =IF(K25="Có",COUNTIF($K$5:K25,"Có"),"")
A26: DM-14 | B26: Danh mục hàng & NCC | C26: DM08 | D26: Nhóm nhà cung cấp | E26: Thêm nhóm "NCC hàng hoá", gán cho NCC. | F26: Lọc NCC theo nhóm đúng. | G26: TH1 | H26: P3 | I26: 0.25 | K26: Không | L26: =IF(K26="Có","Chờ",ROUNDUP(SUMIFS($I$5:I26,$K$5:K26,"Không")/'Hướng dẫn'!$C$7,0)) -> 3 | M26: =IF(ISNUMBER(L26),WORKDAY('Hướng dẫn'!$C$6,L26-1),"") -> 46324 | P26: Chưa test | R26: |TH1| | S26: =IF(K26="Có",COUNTIF($K$5:K26,"Có"),"")
A27: CS-01 | B27: Chính sách & cài đặt | C27: MH04 | D27: CK thẳng % trên đơn | E27: Khai CK 7% cho NCC Trung Hậu, có hiệu lực. | F27: Phiếu nhập của NCC tự áp 7%. | G27: TH1, TH4 | H27: P1 | I27: 0.75 | K27: Không | L27: =IF(K27="Có","Chờ",ROUNDUP(SUMIFS($I$5:I27,$K$5:K27,"Không")/'Hướng dẫn'!$C$7,0)) -> 3 | M27: =IF(ISNUMBER(L27),WORKDAY('Hướng dẫn'!$C$6,L27-1),"") -> 46324 | P27: Chưa test | R27: |TH1|TH4| | S27: =IF(K27="Có",COUNTIF($K$5:K27,"Có"),"")
A28: CS-02 | B28: Chính sách & cài đặt | C28: MH04 | D28: CK bằng tiền trên tổng đơn | E28: Khai CK 2.000.000 trên tổng đơn. | F28: Tự trừ và chia vào giá từng dòng; tổng đúng. | G28: TH2 | H28: P1 | I28: 0.5 | K28: Không | L28: =IF(K28="Có","Chờ",ROUNDUP(SUMIFS($I$5:I28,$K$5:K28,"Không")/'Hướng dẫn'!$C$7,0)) -> 3 | M28: =IF(ISNUMBER(L28),WORKDAY('Hướng dẫn'!$C$6,L28-1),"") -> 46324 | P28: Chưa test | R28: |TH2| | S28: =IF(K28="Có",COUNTIF($K$5:K28,"Có"),"")
A29: CS-03 | B29: Chính sách & cài đặt | C29: MH04 | D29: CK bậc số lượng | E29: Khai bậc <50: 0%, 50–99: 3%, 100–199: 5%, ≥200: 7%. | F29: Đúng bậc theo SL, không áp nhầm bậc 7%. | G29: TH7, VD2, VD8 | H29: P1 | I29: 0.75 | K29: Không | L29: =IF(K29="Có","Chờ",ROUNDUP(SUMIFS($I$5:I29,$K$5:K29,"Không")/'Hướng dẫn'!$C$7,0)) -> 3 | M29: =IF(ISNUMBER(L29),WORKDAY('Hướng dẫn'!$C$6,L29-1),"") -> 46324 | P29: Chưa test | R29: |TH7|VD2|VD8| | S29: =IF(K29="Có",COUNTIF($K$5:K29,"Có"),"")
A30: CS-04 | B30: Chính sách & cài đặt | C30: MH04 | D30: CK thanh toán đúng hạn (CKTT) | E30: Khai CKTT 2% nếu trả đúng hạn. | F30: Hiện CKTT dự kiến trên phiếu; chỉ ghi khi trả đúng hạn. | G30: TH4 | H30: P1 | I30: 0.5 | K30: Không | L30: =IF(K30="Có","Chờ",ROUNDUP(SUMIFS($I$5:I30,$K$5:K30,"Không")/'Hướng dẫn'!$C$7,0)) -> 3 | M30: =IF(ISNUMBER(L30),WORKDAY('Hướng dẫn'!$C$6,L30-1),"") -> 46324 | P30: Chưa test | R30: |TH4| | S30: =IF(K30="Có",COUNTIF($K$5:K30,"Có"),"")
A31: CS-05 | B31: Chính sách & cài đặt | C31: MH04 | D31: Khuyến mại mua X tặng Y | E31: Khai 2 chương trình: KM người bán (chia giá) và KM người tiêu dùng (không chia). | F31: Phiếu tự thêm dòng quà; chia giá thì giá vốn giảm, không chia thì không. | G31: TH14 | H31: P1 | I31: 1 | K31: Không | L31: =IF(K31="Có","Chờ",ROUNDUP(SUMIFS($I$5:I31,$K$5:K31,"Không")/'Hướng dẫn'!$C$7,0)) -> 4 | M31: =IF(ISNUMBER(L31),WORKDAY('Hướng dẫn'!$C$6,L31-1),"") -> 46325 | P31: Chưa test | R31: |TH14| | S31: =IF(K31="Có",COUNTIF($K$5:K31,"Có"),"")
A32: CS-06 | B32: Chính sách & cài đặt | C32: MH04 | D32: Thưởng doanh số kỳ | E32: Khai thưởng tháng 300 triệu → 3%. | F32: Màn Tính thưởng nhận đúng chính sách. | G32: TH8 | H32: P1 | I32: 0.75 | K32: Không | L32: =IF(K32="Có","Chờ",ROUNDUP(SUMIFS($I$5:I32,$K$5:K32,"Không")/'Hướng dẫn'!$C$7,0)) -> 4 | M32: =IF(ISNUMBER(L32),WORKDAY('Hướng dẫn'!$C$6,L32-1),"") -> 46325 | P32: Chưa test | R32: |TH8| | S32: =IF(K32="Có",COUNTIF($K$5:K32,"Có"),"")
A33: CS-07 | B33: Chính sách & cài đặt | C33: MH04 | D33: Chỉ tiêu theo nhãn | E33: Khai chỉ tiêu Anlene tháng 500 triệu, đạt 110% → 3%. | F33: Tính đúng tỷ lệ hoàn thành. | G33: TH15 | H33: P1 | I33: 0.5 | K33: Không | L33: =IF(K33="Có","Chờ",ROUNDUP(SUMIFS($I$5:I33,$K$5:K33,"Không")/'Hướng dẫn'!$C$7,0)) -> 4 | M33: =IF(ISNUMBER(L33),WORKDAY('Hướng dẫn'!$C$6,L33-1),"") -> 46325 | P33: Chưa test | R33: |TH15| | S33: =IF(K33="Có",COUNTIF($K$5:K33,"Có"),"")
A34: CS-08 | B34: Chính sách & cài đặt | C34: MH04 | D34: Thưởng theo giai đoạn | E34: Khai các giai đoạn trong tháng. | F34: Mỗi giai đoạn tính trên doanh số của chính nó. | G34: TH16 | H34: P1 | I34: 0.75 | K34: Không | L34: =IF(K34="Có","Chờ",ROUNDUP(SUMIFS($I$5:I34,$K$5:K34,"Không")/'Hướng dẫn'!$C$7,0)) -> 4 | M34: =IF(ISNUMBER(L34),WORKDAY('Hướng dẫn'!$C$6,L34-1),"") -> 46325 | P34: Chưa test | R34: |TH16| | S34: =IF(K34="Có",COUNTIF($K$5:K34,"Có"),"")
A35: CS-09 | B35: Chính sách & cài đặt | C35: MH04 | D35: Hạn mức công nợ | E35: Khai hạn mức NCC 600 triệu; hạn mức nhãn Anlene 2 tỷ chia chi nhánh. | F35: Phiếu kiểm hạn mức đúng; phân bổ chi nhánh đúng. | G35: TH3, TH12, TH13, TH17 | H35: P1 | I35: 1 | K35: Không | L35: =IF(K35="Có","Chờ",ROUNDUP(SUMIFS($I$5:I35,$K$5:K35,"Không")/'Hướng dẫn'!$C$7,0)) -> 4 | M35: =IF(ISNUMBER(L35),WORKDAY('Hướng dẫn'!$C$6,L35-1),"") -> 46325 | P35: Chưa test | R35: |TH3|TH12|TH13|TH17| | S35: =IF(K35="Có",COUNTIF($K$5:K35,"Có"),"")
A36: CS-10 | B36: Chính sách & cài đặt | C36: MH04 | D36: Điều khoản thanh toán | E36: Khai hạn 10 / 15 ngày làm việc, tính từ ngày hoá đơn. | F36: Hạn tự tính trừ thứ 7, CN, ngày lễ. | G36: TH1, TH18 | H36: P1 | I36: 0.5 | K36: Không | L36: =IF(K36="Có","Chờ",ROUNDUP(SUMIFS($I$5:I36,$K$5:K36,"Không")/'Hướng dẫn'!$C$7,0)) -> 4 | M36: =IF(ISNUMBER(L36),WORKDAY('Hướng dẫn'!$C$6,L36-1),"") -> 46325 | P36: Chưa test | R36: |TH1|TH18| | S36: =IF(K36="Có",COUNTIF($K$5:K36,"Có"),"")
A37: CS-11 | B37: Chính sách & cài đặt | C37: MH04 | D37: Chỉ tiêu cung ứng chi nhánh | E37: Khai chỉ tiêu cung ứng cho 3 chi nhánh. | F37: Hiện đúng ở màn hạn mức. | G37: TH17 | H37: P3 | I37: 0.5 | K37: Không | L37: =IF(K37="Có","Chờ",ROUNDUP(SUMIFS($I$5:I37,$K$5:K37,"Không")/'Hướng dẫn'!$C$7,0)) -> 4 | M37: =IF(ISNUMBER(L37),WORKDAY('Hướng dẫn'!$C$6,L37-1),"") -> 46325 | P37: Chưa test | R37: |TH17| | S37: =IF(K37="Có",COUNTIF($K$5:K37,"Có"),"")
A38: CS-12 | B38: Chính sách & cài đặt | C38: MH04 | D38: Hiệu lực, tạm ngừng, trùng | E38: Cho 1 chính sách hết hạn; tạm ngừng 1 cái; khai 2 chính sách chồng nhau. | F38: Hết hạn / tạm ngừng không áp nữa; chồng nhau áp theo ưu tiên, không cộng trùng. | H38: P1 | I38: 0.75 | K38: Không | L38: =IF(K38="Có","Chờ",ROUNDUP(SUMIFS($I$5:I38,$K$5:K38,"Không")/'Hướng dẫn'!$C$7,0)) -> 4 | M38: =IF(ISNUMBER(L38),WORKDAY('Hướng dẫn'!$C$6,L38-1),"") -> 46325 | P38: Chưa test | S38: =IF(K38="Có",COUNTIF($K$5:K38,"Có"),"")
A39: CS-13 | B39: Chính sách & cài đặt | C39: MH04 | D39: Bảng chiết khấu theo mã & Excel | E39: Khai CK theo từng mã có ĐVT; nhập từ Excel. | F39: Dòng hàng nhận đúng CK theo mã và ĐVT. | H39: P2 | I39: 0.75 | K39: Không | L39: =IF(K39="Có","Chờ",ROUNDUP(SUMIFS($I$5:I39,$K$5:K39,"Không")/'Hướng dẫn'!$C$7,0)) -> 4 | M39: =IF(ISNUMBER(L39),WORKDAY('Hướng dẫn'!$C$6,L39-1),"") -> 46325 | P39: Chưa test | S39: =IF(K39="Có",COUNTIF($K$5:K39,"Có"),"")
A40: CS-14 | B40: Chính sách & cài đặt | C40: MH12 | D40: Cài đặt mua hàng | E40: Khai ngày lễ, số ngày báo trước hạn, % lệch giá cảnh báo, tài khoản mặc định, số dư nhãn đầu kỳ. | F40: Đổi cài đặt thì phiếu / cảnh báo đổi theo. | G40: TH18 | H40: P1 | I40: 1 | K40: Không | L40: =IF(K40="Có","Chờ",ROUNDUP(SUMIFS($I$5:I40,$K$5:K40,"Không")/'Hướng dẫn'!$C$7,0)) -> 5 | M40: =IF(ISNUMBER(L40),WORKDAY('Hướng dẫn'!$C$6,L40-1),"") -> 46328 | P40: Chưa test | R40: |TH18| | S40: =IF(K40="Có",COUNTIF($K$5:K40,"Có"),"")
A41: CT-01 | B41: Chứng từ mua hàng (MH03) | C41: MH03 | D41: Đơn đặt hàng | E41: Lập đơn đặt: chọn NCC, hàng, ĐVT, SL; lưu. | F41: Số đơn tự sinh; xuất hiện ở danh sách; chưa ghi sổ. | G41: TH5 | H41: P1 | I41: 0.75 | K41: Không | L41: =IF(K41="Có","Chờ",ROUNDUP(SUMIFS($I$5:I41,$K$5:K41,"Không")/'Hướng dẫn'!$C$7,0)) -> 5 | M41: =IF(ISNUMBER(L41),WORKDAY('Hướng dẫn'!$C$6,L41-1),"") -> 46328 | P41: Chưa test | R41: |TH5| | S41: =IF(K41="Có",COUNTIF($K$5:K41,"Có"),"")
...

Sheet 25 tình huống
A1: 25 TÌNH HUỐNG KẾ TOÁN GỬI — ĐÃ ỔN CHƯA?
A2: Tự tính từ sheet "Danh sách test": một tình huống chỉ "Đạt" khi mọi mục test có gắn tình huống đó đều Đạt (kể cả mục chức năng lẻ).
A4: Tình huống | B4: Nội dung | C4: Con số / kết quả phải ra | D4: Máy tự kiểm | E4: Số mục test | F4: Đạt | G4: Lỗi | H4: Đang chờ | I4: Trạng thái | J4: Ghi chú
A5: TH1 | B5: CK thẳng 7%, hạn 10 ngày làm việc | C5: Công nợ 39.082.320, hạn 15/10; ghi 1561 / 1331 / 331 | D5: Đạt 26/10 | E5: =COUNTIFS('Danh sách test'!$R$5:$R$127,"*|TH1|*") -> 7 | F5: =COUNTIFS('Danh sách test'!$R$5:$R$127,"*|TH1|*",'Danh sách test'!$P$5:$P$127,"Đạt") -> 0 | G5: =COUNTIFS('Danh sách test'!$R$5:$R$127,"*|TH1|*",'Danh sách test'!$P$5:$P$127,"Lỗi")+COUNTIFS('Danh sách test'!$R$5:$R$127,"*|TH1|*",'Danh sách test'!$P$5:$P$127,"Đã sửa – chờ test lại") -> 0 | H5: =COUNTIFS('Danh sách test'!$R$5:$R$127,"*|TH1|*",'Danh sách test'!$P$5:$P$127,"Chờ người / dữ liệu") -> 0 | I5: =IF(E5=0,"",IF(F5=E5,"Đạt",IF(G5>0,"Có lỗi",IF(H5>0,"Đang chờ",IF(F5>0,"Đang test","Chưa test"))))) -> Chưa test
A6: TH2 | B6: CK tiền 2 triệu + quà 5 thùng không HĐ | C6: 48.860.000; quà chứng từ riêng, Có 711 | D6: Đạt 26/10 | E6: =COUNTIFS('Danh sách test'!$R$5:$R$127,"*|TH2|*") -> 5 | F6: =COUNTIFS('Danh sách test'!$R$5:$R$127,"*|TH2|*",'Danh sách test'!$P$5:$P$127,"Đạt") -> 0 | G6: =COUNTIFS('Danh sách test'!$R$5:$R$127,"*|TH2|*",'Danh sách test'!$P$5:$P$127,"Lỗi")+COUNTIFS('Danh sách test'!$R$5:$R$127,"*|TH2|*",'Danh sách test'!$P$5:$P$127,"Đã sửa – chờ test lại") -> 0 | H6: =COUNTIFS('Danh sách test'!$R$5:$R$127,"*|TH2|*",'Danh sách test'!$P$5:$P$127,"Chờ người / dữ liệu") -> 1 | I6: =IF(E6=0,"",IF(F6=E6,"Đạt",IF(G6>0,"Có lỗi",IF(H6>0,"Đang chờ",IF(F6>0,"Đang test","Chưa test"))))) -> Đang chờ
A7: TH3 | B7: Hạn mức 600 triệu | C7: Nhập 117.450.000 còn 32.550.000; đặt thêm 40 triệu vượt 7.450.000 → chặn | D7: Đạt 26/10 | E7: =COUNTIFS('Danh sách test'!$R$5:$R$127,"*|TH3|*") -> 4 | F7: =COUNTIFS('Danh sách test'!$R$5:$R$127,"*|TH3|*",'Danh sách test'!$P$5:$P$127,"Đạt") -> 0 | G7: =COUNTIFS('Danh sách test'!$R$5:$R$127,"*|TH3|*",'Danh sách test'!$P$5:$P$127,"Lỗi")+COUNTIFS('Danh sách test'!$R$5:$R$127,"*|TH3|*",'Danh sách test'!$P$5:$P$127,"Đã sửa – chờ test lại") -> 0 | H7: =COUNTIFS('Danh sách test'!$R$5:$R$127,"*|TH3|*",'Danh sách test'!$P$5:$P$127,"Chờ người / dữ liệu") -> 0 | I7: =IF(E7=0,"",IF(F7=E7,"Đạt",IF(G7>0,"Có lỗi",IF(H7>0,"Đang chờ",IF(F7>0,"Đang test","Chưa test"))))) -> Chưa test
A8: TH4 | B8: CK 7% + CKTT 2% | C8: Công nợ 39.082.320; trả đúng hạn CKTT 781.646; quá hạn không | D8: Đạt 26/10 | E8: =COUNTIFS('Danh sách test'!$R$5:$R$127,"*|TH4|*") -> 4 | F8: =COUNTIFS('Danh sách test'!$R$5:$R$127,"*|TH4|*",'Danh sách test'!$P$5:$P$127,"Đạt") -> 0 | G8: =COUNTIFS('Danh sách test'!$R$5:$R$127,"*|TH4|*",'Danh sách test'!$P$5:$P$127,"Lỗi")+COUNTIFS('Danh sách test'!$R$5:$R$127,"*|TH4|*",'Danh sách test'!$P$5:$P$127,"Đã sửa – chờ test lại") -> 0 | H8: =COUNTIFS('Danh sách test'!$R$5:$R$127,"*|TH4|*",'Danh sách test'!$P$5:$P$127,"Chờ người / dữ liệu") -> 0 | I8: =IF(E8=0,"",IF(F8=E8,"Đạt",IF(G8>0,"Có lỗi",IF(H8>0,"Đang chờ",IF(F8>0,"Đang test","Chưa test"))))) -> Chưa test
A9: TH5 | B9: Ứng trước 100% theo đơn DH005 | C9: HĐ 3185 tự đối trừ; đối chiếu 3 bên khớp | D9: Đạt 26/10 | E9: =COUNTIFS('Danh sách test'!$R$5:$R$127,"*|TH5|*") -> 4 | F9: =COUNTIFS('Danh sách test'!$R$5:$R$127,"*|TH5|*",'Danh sách test'!$P$5:$P$127,"Đạt") -> 0 | G9: =COUNTIFS('Danh sách test'!$R$5:$R$127,"*|TH5|*",'Danh sách test'!$P$5:$P$127,"Lỗi")+COUNTIFS('Danh sách test'!$R$5:$R$127,"*|TH5|*",'Danh sách test'!$P$5:$P$127,"Đã sửa – chờ test lại") -> 0 | H9: =COUNTIFS('Danh sách test'!$R$5:$R$127,"*|TH5|*",'Danh sách test'!$P$5:$P$127,"Chờ người / dữ liệu") -> 0 | I9: =IF(E9=0,"",IF(F9=E9,"Đạt",IF(G9>0,"Có lỗi",IF(H9>0,"Đang chờ",IF(F9>0,"Đang test","Chưa test"))))) -> Chưa test
A10: TH6 | B10: Bán hàng có CK từng dòng (phía bán) | C10: Phải thu 35.700.000 | D10: Đạt công thức | E10: =COUNTIFS('Danh sách test'!$R$5:$R$127,"*|TH6|*") -> 1 | F10: =COUNTIFS('Danh sách test'!$R$5:$R$127,"*|TH6|*",'Danh sách test'!$P$5:$P$127,"Đạt") -> 0 | G10: =COUNTIFS('Danh sách test'!$R$5:$R$127,"*|TH6|*",'Danh sách test'!$P$5:$P$127,"Lỗi")+COUNTIFS('Danh sách test'!$R$5:$R$127,"*|TH6|*",'Danh sách test'!$P$5:$P$127,"Đã sửa – chờ test lại") -> 0 | H10: =COUNTIFS('Danh sách test'!$R$5:$R$127,"*|TH6|*",'Danh sách test'!$P$5:$P$127,"Chờ người / dữ liệu") -> 1 | I10: =IF(E10=0,"",IF(F10=E10,"Đạt",IF(G10>0,"Có lỗi",IF(H10>0,"Đang chờ",IF(F10>0,"Đang test","Chưa test"))))) -> Đang chờ
A11: TH7 | B11: Bậc CK số lượng (phía bán) | C11: 150 lon được 5%, không áp nhầm 7% | D11: Đạt công thức | E11: =COUNTIFS('Danh sách test'!$R$5:$R$127,"*|TH7|*") -> 2 | F11: =COUNTIFS('Danh sách test'!$R$5:$R$127,"*|TH7|*",'Danh sách test'!$P$5:$P$127,"Đạt") -> 0 | G11: =COUNTIFS('Danh sách test'!$R$5:$R$127,"*|TH7|*",'Danh sách test'!$P$5:$P$127,"Lỗi")+COUNTIFS('Danh sách test'!$R$5:$R$127,"*|TH7|*",'Danh sách test'!$P$5:$P$127,"Đã sửa – chờ test lại") -> 0 | H11: =COUNTIFS('Danh sách test'!$R$5:$R$127,"*|TH7|*",'Danh sách test'!$P$5:$P$127,"Chờ người / dữ liệu") -> 1 | I11: =IF(E11=0,"",IF(F11=E11,"Đạt",IF(G11>0,"Có lỗi",IF(H11>0,"Đang chờ",IF(F11>0,"Đang test","Chưa test"))))) -> Đang chờ
A12: TH8 | B12: Thưởng doanh số tháng | C12: 9.000.000 + VAT 720.000 = giảm nợ 9.720.000 | D12: Đạt 26/10 | E12: =COUNTIFS('Danh sách test'!$R$5:$R$127,"*|TH8|*") -> 4 | F12: =COUNTIFS('Danh sách test'!$R$5:$R$127,"*|TH8|*",'Danh sách test'!$P$5:$P$127,"Đạt") -> 0 | G12: =COUNTIFS('Danh sách test'!$R$5:$R$127,"*|TH8|*",'Danh sách test'!$P$5:$P$127,"Lỗi")+COUNTIFS('Danh sách test'!$R$5:$R$127,"*|TH8|*",'Danh sách test'!$P$5:$P$127,"Đã sửa – chờ test lại") -> 0 | H12: =COUNTIFS('Danh sách test'!$R$5:$R$127,"*|TH8|*",'Danh sách test'!$P$5:$P$127,"Chờ người / dữ liệu") -> 0 | I12: =IF(E12=0,"",IF(F12=E12,"Đạt",IF(G12>0,"Có lỗi",IF(H12>0,"Đang chờ",IF(F12>0,"Đang test","Chưa test"))))) -> Chưa test
A13: TH9 | B13: CK + tặng hàng (phía bán) | C13: Theo tài liệu | D13: Đạt công thức | E13: =COUNTIFS('Danh sách test'!$R$5:$R$127,"*|TH9|*") -> 1 | F13: =COUNTIFS('Danh sách test'!$R$5:$R$127,"*|TH9|*",'Danh sách test'!$P$5:$P$127,"Đạt") -> 0 | G13: =COUNTIFS('Danh sách test'!$R$5:$R$127,"*|TH9|*",'Danh sách test'!$P$5:$P$127,"Lỗi")+COUNTIFS('Danh sách test'!$R$5:$R$127,"*|TH9|*",'Danh sách test'!$P$5:$P$127,"Đã sửa – chờ test lại") -> 0 | H13: =COUNTIFS('Danh sách test'!$R$5:$R$127,"*|TH9|*",'Danh sách test'!$P$5:$P$127,"Chờ người / dữ liệu") -> 1 | I13: =IF(E13=0,"",IF(F13=E13,"Đạt",IF(G13>0,"Có lỗi",IF(H13>0,"Đang chờ",IF(F13>0,"Đang test","Chưa test"))))) -> Đang chờ
A14: TH10 | B14: Đặt hàng có CK (phía bán) | C14: Theo tài liệu | D14: Đạt công thức | E14: =COUNTIFS('Danh sách test'!$R$5:$R$127,"*|TH10|*") -> 1 | F14: =COUNTIFS('Danh sách test'!$R$5:$R$127,"*|TH10|*",'Danh sách test'!$P$5:$P$127,"Đạt") -> 0 | G14: =COUNTIFS('Danh sách test'!$R$5:$R$127,"*|TH10|*",'Danh sách test'!$P$5:$P$127,"Lỗi")+COUNTIFS('Danh sách test'!$R$5:$R$127,"*|TH10|*",'Danh sách test'!$P$5:$P$127,"Đã sửa – chờ test lại") -> 0 | H14: =COUNTIFS('Danh sách test'!$R$5:$R$127,"*|TH10|*",'Danh sách test'!$P$5:$P$127,"Chờ người / dữ liệu") -> 1 | I14: =IF(E14=0,"",IF(F14=E14,"Đạt",IF(G14>0,"Có lỗi",IF(H14>0,"Đang chờ",IF(F14>0,"Đang test","Chưa test"))))) -> Đang chờ
A15: TH11 | B15: Một HĐ trả 3 đợt | C15: 30 / 40 / 38 triệu; trạng thái từng đợt đúng | D15: Đạt 26/10 | E15: =COUNTIFS('Danh sách test'!$R$5:$R$127,"*|TH11|*") -> 2 | F15: =COUNTIFS('Danh sách test'!$R$5:$R$127,"*|TH11|*",'Danh sách test'!$P$5:$P$127,"Đạt") -> 0 | G15: =COUNTIFS('Danh sách test'!$R$5:$R$127,"*|TH11|*",'Danh sách test'!$P$5:$P$127,"Lỗi")+COUNTIFS('Danh sách test'!$R$5:$R$127,"*|TH11|*",'Danh sách test'!$P$5:$P$127,"Đã sửa – chờ test lại") -> 0 | H15: =COUNTIFS('Danh sách test'!$R$5:$R$127,"*|TH11|*",'Danh sách test'!$P$5:$P$127,"Chờ người / dữ liệu") -> 0 | I15: =IF(E15=0,"",IF(F15=E15,"Đạt",IF(G15>0,"Có lỗi",IF(H15>0,"Đang chờ",IF(F15>0,"Đang test","Chưa test"))))) -> Chưa test
A16: TH12 | B16: Nợ cũ 480 + 108 triệu | C16: 588 triệu, còn 12 triệu → duyệt bình thường | D16: Đạt 26/10 | E16: =COUNTIFS('Danh sách test'!$R$5:$R$127,"*|TH12|*") -> 3 | F16: =COUNTIFS('Danh sách test'!$R$5:$R$127,"*|TH12|*",'Danh sách test'!$P$5:$P$127,"Đạt") -> 0 | G16: =COUNTIFS('Danh sách test'!$R$5:$R$127,"*|TH12|*",'Danh sách test'!$P$5:$P$127,"Lỗi")+COUNTIFS('Danh sách test'!$R$5:$R$127,"*|TH12|*",'Danh sách test'!$P$5:$P$127,"Đã sửa – chờ test lại") -> 0 | H16: =COUNTIFS('Danh sách test'!$R$5:$R$127,"*|TH12|*",'Danh sách test'!$P$5:$P$127,"Chờ người / dữ liệu") -> 0 | I16: =IF(E16=0,"",IF(F16=E16,"Đạt",IF(G16>0,"Có lỗi",IF(H16>0,"Đang chờ",IF(F16>0,"Đang test","Chưa test"))))) -> Chưa test
A17: TH13 | B17: Nợ 550 + 108 triệu | C17: Vượt 58 triệu → chặn; trả bớt hoặc duyệt ngoại lệ | D17: Đạt 26/10 | E17: =COUNTIFS('Danh sách test'!$R$5:$R$127,"*|TH13|*") -> 3 | F17: =COUNTIFS('Danh sách test'!$R$5:$R$127,"*|TH13|*",'Danh sách test'!$P$5:$P$127,"Đạt") -> 0 | G17: =COUNTIFS('Danh sách test'!$R$5:$R$127,"*|TH13|*",'Danh sách test'!$P$5:$P$127,"Lỗi")+COUNTIFS('Danh sách test'!$R$5:$R$127,"*|TH13|*",'Danh sách test'!$P$5:$P$127,"Đã sửa – chờ test lại") -> 0 | H17: =COUNTIFS('Danh sách test'!$R$5:$R$127,"*|TH13|*",'Danh sách test'!$P$5:$P$127,"Chờ người / dữ liệu") -> 0 | I17: =IF(E17=0,"",IF(F17=E17,"Đạt",IF(G17>0,"Có lỗi",IF(H17>0,"Đang chờ",IF(F17>0,"Đang test","Chưa test"))))) -> Chưa test
A18: TH14 | B18: KM người bán / người tiêu dùng | C18: KM người bán 120 chia giá; KM NTD 240 không chia | D18: Đạt 26/10 | E18: =COUNTIFS('Danh sách test'!$R$5:$R$127,"*|TH14|*") -> 3 | F18: =COUNTIFS('Danh sách test'!$R$5:$R$127,"*|TH14|*",'Danh sách test'!$P$5:$P$127,"Đạt") -> 0 | G18: =COUNTIFS('Danh sách test'!$R$5:$R$127,"*|TH14|*",'Danh sách test'!$P$5:$P$127,"Lỗi")+COUNTIFS('Danh sách test'!$R$5:$R$127,"*|TH14|*",'Danh sách test'!$P$5:$P$127,"Đã sửa – chờ test lại") -> 0 | H18: =COUNTIFS('Danh sách test'!$R$5:$R$127,"*|TH14|*",'Danh sách test'!$P$5:$P$127,"Chờ người / dữ liệu") -> 0 | I18: =IF(E18=0,"",IF(F18=E18,"Đạt",IF(G18>0,"Có lỗi",IF(H18>0,"Đang chờ",IF(F18>0,"Đang test","Chưa test"))))) -> Chưa test
A19: TH15 | B19: Chỉ tiêu nhãn 110% | C19: Thưởng 3% = 16.500.000 | D19: Đạt 26/10 | E19: =COUNTIFS('Danh sách test'!$R$5:$R$127,"*|TH15|*") -> 3 | F19: =COUNTIFS('Danh sách test'!$R$5:$R$127,"*|TH15|*",'Danh sách test'!$P$5:$P$127,"Đạt") -> 0 | G19: =COUNTIFS('Danh sách test'!$R$5:$R$127,"*|TH15|*",'Danh sách test'!$P$5:$P$127,"Lỗi")+COUNTIFS('Danh sách test'!$R$5:$R$127,"*|TH15|*",'Danh sách test'!$P$5:$P$127,"Đã sửa – chờ test lại") -> 0 | H19: =COUNTIFS('Danh sách test'!$R$5:$R$127,"*|TH15|*",'Danh sách test'!$P$5:$P$127,"Chờ người / dữ liệu") -> 0 | I19: =IF(E19=0,"",IF(F19=E19,"Đạt",IF(G19>0,"Có lỗi",IF(H19>0,"Đang chờ",IF(F19>0,"Đang test","Chưa test"))))) -> Chưa test
A20: TH16 | B20: Thưởng theo giai đoạn | C20: Mỗi giai đoạn tính riêng, không trùng | D20: Đạt 26/10 | E20: =COUNTIFS('Danh sách test'!$R$5:$R$127,"*|TH16|*") -> 3 | F20: =COUNTIFS('Danh sách test'!$R$5:$R$127,"*|TH16|*",'Danh sách test'!$P$5:$P$127,"Đạt") -> 0 | G20: =COUNTIFS('Danh sách test'!$R$5:$R$127,"*|TH16|*",'Danh sách test'!$P$5:$P$127,"Lỗi")+COUNTIFS('Danh sách test'!$R$5:$R$127,"*|TH16|*",'Danh sách test'!$P$5:$P$127,"Đã sửa – chờ test lại") -> 0 | H20: =COUNTIFS('Danh sách test'!$R$5:$R$127,"*|TH16|*",'Danh sách test'!$P$5:$P$127,"Chờ người / dữ liệu") -> 0 | I20: =IF(E20=0,"",IF(F20=E20,"Đạt",IF(G20>0,"Có lỗi",IF(H20>0,"Đang chờ",IF(F20>0,"Đang test","Chưa test"))))) -> Chưa test
A21: TH17 | B21: Hạn mức nhãn 2 tỷ chia chi nhánh | C21: ND 500 · PT 600 · HCM 400 · chưa phân bổ 500; điều chuyển có vết | D21: Đạt 26/10 | E21: =COUNTIFS('Danh sách test'!$R$5:$R$127,"*|TH17|*") -> 4 | F21: =COUNTIFS('Danh sách test'!$R$5:$R$127,"*|TH17|*",'Danh sách test'!$P$5:$P$127,"Đạt") -> 0 | G21: =COUNTIFS('Danh sách test'!$R$5:$R$127,"*|TH17|*",'Danh sách test'!$P$5:$P$127,"Lỗi")+COUNTIFS('Danh sách test'!$R$5:$R$127,"*|TH17|*",'Danh sách test'!$P$5:$P$127,"Đã sửa – chờ test lại") -> 0 | H21: =COUNTIFS('Danh sách test'!$R$5:$R$127,"*|TH17|*",'Danh sách test'!$P$5:$P$127,"Chờ người / dữ liệu") -> 0 | I21: =IF(E21=0,"",IF(F21=E21,"Đạt",IF(G21>0,"Có lỗi",IF(H21>0,"Đang chờ",IF(F21>0,"Đang test","Chưa test"))))) -> Chưa test
A22: TH18 | B22: Hạn theo ngày làm việc + tuổi nợ | C22: Trừ ngày lễ; 6 nhóm tuổi nợ; cảnh báo nợ quá hạn | D22: Đạt 26/10 | E22: =COUNTIFS('Danh sách test'!$R$5:$R$127,"*|TH18|*") -> 5 | F22: =COUNTIFS('Danh sách test'!$R$5:$R$127,"*|TH18|*",'Danh sách test'!$P$5:$P$127,"Đạt") -> 0 | G22: =COUNTIFS('Danh sách test'!$R$5:$R$127,"*|TH18|*",'Danh sách test'!$P$5:$P$127,"Lỗi")+COUNTIFS('Danh sách test'!$R$5:$R$127,"*|TH18|*",'Danh sách test'!$P$5:$P$127,"Đã sửa – chờ test lại") -> 0 | H22: =COUNTIFS('Danh sách test'!$R$5:$R$127,"*|TH18|*",'Danh sách test'!$P$5:$P$127,"Chờ người / dữ liệu") -> 0 | I22: =IF(E22=0,"",IF(F22=E22,"Đạt",IF(G22>0,"Có lỗi",IF(H22>0,"Đang chờ",IF(F22>0,"Đang test","Chưa test"))))) -> Chưa test
A23: TH19 | B23: Lô & hạn dùng | C23: Lô A 15/11, B 30/11; cảnh báo cận date | D23: Đạt 26/10 | E23: =COUNTIFS('Danh sách test'!$R$5:$R$127,"*|TH19|*") -> 3 | F23: =COUNTIFS('Danh sách test'!$R$5:$R$127,"*|TH19|*",'Danh sách test'!$P$5:$P$127,"Đạt") -> 0 | G23: =COUNTIFS('Danh sách test'!$R$5:$R$127,"*|TH19|*",'Danh sách test'!$P$5:$P$127,"Lỗi")+COUNTIFS('Danh sách test'!$R$5:$R$127,"*|TH19|*",'Danh sách test'!$P$5:$P$127,"Đã sửa – chờ test lại") -> 0 | H23: =COUNTIFS('Danh sách test'!$R$5:$R$127,"*|TH19|*",'Danh sách test'!$P$5:$P$127,"Chờ người / dữ liệu") -> 0 | I23: =IF(E23=0,"",IF(F23=E23,"Đạt",IF(G23>0,"Có lỗi",IF(H23>0,"Đang chờ",IF(F23>0,"Đang test","Chưa test"))))) -> Chưa test
A24: TH20 | B24: Quà tặng nhiều nguồn | C24: NCC tặng 100, mua 50 có VAT + 30 không VAT; xuất vượt chặn | D24: Đạt 26/10 | E24: =COUNTIFS('Danh sách test'!$R$5:$R$127,"*|TH20|*") -> 4 | F24: =COUNTIFS('Danh sách test'!$R$5:$R$127,"*|TH20|*",'Danh sách test'!$P$5:$P$127,"Đạt") -> 0 | G24: =COUNTIFS('Danh sách test'!$R$5:$R$127,"*|TH20|*",'Danh sách test'!$P$5:$P$127,"Lỗi")+COUNTIFS('Danh sách test'!$R$5:$R$127,"*|TH20|*",'Danh sách test'!$P$5:$P$127,"Đã sửa – chờ test lại") -> 0 | H24: =COUNTIFS('Danh sách test'!$R$5:$R$127,"*|TH20|*",'Danh sách test'!$P$5:$P$127,"Chờ người / dữ liệu") -> 1 | I24: =IF(E24=0,"",IF(F24=E24,"Đạt",IF(G24>0,"Có lỗi",IF(H24>0,"Đang chờ",IF(F24>0,"Đang test","Chưa test"))))) -> Đang chờ
A25: TH21 | B25: Phân bổ cước 10 triệu | C25: 4,8 / 3,2 / 2 triệu; 489.600 / lon | D25: Đạt 26/10 | E25: =COUNTIFS('Danh sách test'!$R$5:$R$127,"*|TH21|*") -> 3 | F25: =COUNTIFS('Danh sách test'!$R$5:$R$127,"*|TH21|*",'Danh sách test'!$P$5:$P$127,"Đạt") -> 0 | G25: =COUNTIFS('Danh sách test'!$R$5:$R$127,"*|TH21|*",'Danh sách test'!$P$5:$P$127,"Lỗi")+COUNTIFS('Danh sách test'!$R$5:$R$127,"*|TH21|*",'Danh sách test'!$P$5:$P$127,"Đã sửa – chờ test lại") -> 0 | H25: =COUNTIFS('Danh sách test'!$R$5:$R$127,"*|TH21|*",'Danh sách test'!$P$5:$P$127,"Chờ người / dữ liệu") -> 0 | I25: =IF(E25=0,"",IF(F25=E25,"Đạt",IF(G25>0,"Có lỗi",IF(H25>0,"Đang chờ",IF(F25>0,"Đang test","Chưa test"))))) -> Chưa test
A26: TH22 | B26: Phân bổ thưởng theo mã | C26: Giảm giá vốn từng mã, tổng khớp | D26: Đạt 26/10 | E26: =COUNTIFS('Danh sách test'!$R$5:$R$127,"*|TH22|*") -> 2 | F26: =COUNTIFS('Danh sách test'!$R$5:$R$127,"*|TH22|*",'Danh sách test'!$P$5:$P$127,"Đạt") -> 0 | G26: =COUNTIFS('Danh sách test'!$R$5:$R$127,"*|TH22|*",'Danh sách test'!$P$5:$P$127,"Lỗi")+COUNTIFS('Danh sách test'!$R$5:$R$127,"*|TH22|*",'Danh sách test'!$P$5:$P$127,"Đã sửa – chờ test lại") -> 0 | H26: =COUNTIFS('Danh sách test'!$R$5:$R$127,"*|TH22|*",'Danh sách test'!$P$5:$P$127,"Chờ người / dữ liệu") -> 0 | I26: =IF(E26=0,"",IF(F26=E26,"Đạt",IF(G26>0,"Có lỗi",IF(H26>0,"Đang chờ",IF(F26>0,"Đang test","Chưa test"))))) -> Chưa test
A27: TH23 | B27: Trả / đổi hàng | C27: Đổi cùng mã chênh 0; khác mã trả thêm 1.080.000; trả quá bị chặn | D27: Đạt 26/10 | E27: =COUNTIFS('Danh sách test'!$R$5:$R$127,"*|TH23|*") -> 3 | F27: =COUNTIFS('Danh sách test'!$R$5:$R$127,"*|TH23|*",'Danh sách test'!$P$5:$P$127,"Đạt") -> 0 | G27: =COUNTIFS('Danh sách test'!$R$5:$R$127,"*|TH23|*",'Danh sách test'!$P$5:$P$127,"Lỗi")+COUNTIFS('Danh sách test'!$R$5:$R$127,"*|TH23|*",'Danh sách test'!$P$5:$P$127,"Đã sửa – chờ test lại") -> 0 | H27: =COUNTIFS('Danh sách test'!$R$5:$R$127,"*|TH23|*",'Danh sách test'!$P$5:$P$127,"Chờ người / dữ liệu") -> 0 | I27: =IF(E27=0,"",IF(F27=E27,"Đạt",IF(G27>0,"Có lỗi",IF(H27>0,"Đang chờ",IF(F27>0,"Đang test","Chưa test"))))) -> Chưa test
A28: TH24 | B28: Tổng hợp theo ngành / nhóm / mã | C28: Kèm công nợ còn lại theo mã | D28: Đạt 26/10 | E28: =COUNTIFS('Danh sách test'!$R$5:$R$127,"*|TH24|*") -> 3 | F28: =COUNTIFS('Danh sách test'!$R$5:$R$127,"*|TH24|*",'Danh sách test'!$P$5:$P$127,"Đạt") -> 0 | G28: =COUNTIFS('Danh sách test'!$R$5:$R$127,"*|TH24|*",'Danh sách test'!$P$5:$P$127,"Lỗi")+COUNTIFS('Danh sách test'!$R$5:$R$127,"*|TH24|*",'Danh sách test'!$P$5:$P$127,"Đã sửa – chờ test lại") -> 0 | H28: =COUNTIFS('Danh sách test'!$R$5:$R$127,"*|TH24|*",'Danh sách test'!$P$5:$P$127,"Chờ người / dữ liệu") -> 0 | I28: =IF(E28=0,"",IF(F28=E28,"Đạt",IF(G28>0,"Có lỗi",IF(H28>0,"Đang chờ",IF(F28>0,"Đang test","Chưa test"))))) -> Chưa test
A29: TH25 | B29: Giá thực tế sau mọi điều chỉnh | C29: Giá từng dòng = sau CK − quà + chi phí − thưởng | D29: Đạt 26/10 | E29: =COUNTIFS('Danh sách test'!$R$5:$R$127,"*|TH25|*") -> 5 | F29: =COUNTIFS('Danh sách test'!$R$5:$R$127,"*|TH25|*",'Danh sách test'!$P$5:$P$127,"Đạt") -> 0 | G29: =COUNTIFS('Danh sách test'!$R$5:$R$127,"*|TH25|*",'Danh sách test'!$P$5:$P$127,"Lỗi")+COUNTIFS('Danh sách test'!$R$5:$R$127,"*|TH25|*",'Danh sách test'!$P$5:$P$127,"Đã sửa – chờ test lại") -> 0 | H29: =COUNTIFS('Danh sách test'!$R$5:$R$127,"*|TH25|*",'Danh sách test'!$P$5:$P$127,"Chờ người / dữ liệu") -> 0 | I29: =IF(E29=0,"",IF(F29=E29,"Đạt",IF(G29>0,"Có lỗi",IF(H29>0,"Đang chờ",IF(F29>0,"Đang test","Chưa test"))))) -> Chưa test
A30: VD1 | B30: Nhập file Excel của NCC | C30: Đủ dòng, đúng mã, ĐVT, giá, thuế | D30: Chưa có (cần file) | E30: =COUNTIFS('Danh sách test'!$R$5:$R$127,"*|VD1|*") -> 2 | F30: =COUNTIFS('Danh sách test'!$R$5:$R$127,"*|VD1|*",'Danh sách test'!$P$5:$P$127,"Đạt") -> 0 | G30: =COUNTIFS('Danh sách test'!$R$5:$R$127,"*|VD1|*",'Danh sách test'!$P$5:$P$127,"Lỗi")+COUNTIFS('Danh sách test'!$R$5:$R$127,"*|VD1|*",'Danh sách test'!$P$5:$P$127,"Đã sửa – chờ test lại") -> 0 | H30: =COUNTIFS('Danh sách test'!$R$5:$R$127,"*|VD1|*",'Danh sách test'!$P$5:$P$127,"Chờ người / dữ liệu") -> 2 | I30: =IF(E30=0,"",IF(F30=E30,"Đạt",IF(G30>0,"Có lỗi",IF(H30>0,"Đang chờ",IF(F30>0,"Đang test","Chưa test"))))) -> Đang chờ
A31: VD2 | B31: Nhiều thuế suất, bậc SL | C31: Bậc 5%, hạn 15 ngày làm việc | D31: Đạt 26/10 | E31: =COUNTIFS('Danh sách test'!$R$5:$R$127,"*|VD2|*") -> 4 | F31: =COUNTIFS('Danh sách test'!$R$5:$R$127,"*|VD2|*",'Danh sách test'!$P$5:$P$127,"Đạt") -> 0 | G31: =COUNTIFS('Danh sách test'!$R$5:$R$127,"*|VD2|*",'Danh sách test'!$P$5:$P$127,"Lỗi")+COUNTIFS('Danh sách test'!$R$5:$R$127,"*|VD2|*",'Danh sách test'!$P$5:$P$127,"Đã sửa – chờ test lại") -> 0 | H31: =COUNTIFS('Danh sách test'!$R$5:$R$127,"*|VD2|*",'Danh sách test'!$P$5:$P$127,"Chờ người / dữ liệu") -> 0 | I31: =IF(E31=0,"",IF(F31=E31,"Đạt",IF(G31>0,"Có lỗi",IF(H31>0,"Đang chờ",IF(F31>0,"Đang test","Chưa test"))))) -> Chưa test
A32: VD3 | B32: Chi phí bốc xếp theo SL | C32: Phân bổ đúng | D32: Đạt 26/10 | E32: =COUNTIFS('Danh sách test'!$R$5:$R$127,"*|VD3|*") -> 2 | F32: =COUNTIFS('Danh sách test'!$R$5:$R$127,"*|VD3|*",'Danh sách test'!$P$5:$P$127,"Đạt") -> 0 | G32: =COUNTIFS('Danh sách test'!$R$5:$R$127,"*|VD3|*",'Danh sách test'!$P$5:$P$127,"Lỗi")+COUNTIFS('Danh sách test'!$R$5:$R$127,"*|VD3|*",'Danh sách test'!$P$5:$P$127,"Đã sửa – chờ test lại") -> 0 | H32: =COUNTIFS('Danh sách test'!$R$5:$R$127,"*|VD3|*",'Danh sách test'!$P$5:$P$127,"Chờ người / dữ liệu") -> 0 | I32: =IF(E32=0,"",IF(F32=E32,"Đạt",IF(G32>0,"Có lỗi",IF(H32>0,"Đang chờ",IF(F32>0,"Đang test","Chưa test"))))) -> Chưa test
A33: VD4 | B33: Giá cao hơn giá cố định | C33: Cảnh báo 3,9%, không chặn | D33: Đạt 26/10 | E33: =COUNTIFS('Danh sách test'!$R$5:$R$127,"*|VD4|*") -> 5 | F33: =COUNTIFS('Danh sách test'!$R$5:$R$127,"*|VD4|*",'Danh sách test'!$P$5:$P$127,"Đạt") -> 0 | G33: =COUNTIFS('Danh sách test'!$R$5:$R$127,"*|VD4|*",'Danh sách test'!$P$5:$P$127,"Lỗi")+COUNTIFS('Danh sách test'!$R$5:$R$127,"*|VD4|*",'Danh sách test'!$P$5:$P$127,"Đã sửa – chờ test lại") -> 0 | H33: =COUNTIFS('Danh sách test'!$R$5:$R$127,"*|VD4|*",'Danh sách test'!$P$5:$P$127,"Chờ người / dữ liệu") -> 0 | I33: =IF(E33=0,"",IF(F33=E33,"Đạt",IF(G33>0,"Có lỗi",IF(H33>0,"Đang chờ",IF(F33>0,"Đang test","Chưa test"))))) -> Chưa test
A34: VD5 | B34: CK sau mua có HĐ điều chỉnh | C34: Giảm nợ đúng | D34: Đạt 26/10 | E34: =COUNTIFS('Danh sách test'!$R$5:$R$127,"*|VD5|*") -> 2 | F34: =COUNTIFS('Danh sách test'!$R$5:$R$127,"*|VD5|*",'Danh sách test'!$P$5:$P$127,"Đạt") -> 0 | G34: =COUNTIFS('Danh sách test'!$R$5:$R$127,"*|VD5|*",'Danh sách test'!$P$5:$P$127,"Lỗi")+COUNTIFS('Danh sách test'!$R$5:$R$127,"*|VD5|*",'Danh sách test'!$P$5:$P$127,"Đã sửa – chờ test lại") -> 0 | H34: =COUNTIFS('Danh sách test'!$R$5:$R$127,"*|VD5|*",'Danh sách test'!$P$5:$P$127,"Chờ người / dữ liệu") -> 0 | I34: =IF(E34=0,"",IF(F34=E34,"Đạt",IF(G34>0,"Có lỗi",IF(H34>0,"Đang chờ",IF(F34>0,"Đang test","Chưa test"))))) -> Chưa test
A35: VD6 | B35: Trả một phần | C35: Tồn, nợ giảm đúng | D35: Đạt 26/10 | E35: =COUNTIFS('Danh sách test'!$R$5:$R$127,"*|VD6|*") -> 2 | F35: =COUNTIFS('Danh sách test'!$R$5:$R$127,"*|VD6|*",'Danh sách test'!$P$5:$P$127,"Đạt") -> 0 | G35: =COUNTIFS('Danh sách test'!$R$5:$R$127,"*|VD6|*",'Danh sách test'!$P$5:$P$127,"Lỗi")+COUNTIFS('Danh sách test'!$R$5:$R$127,"*|VD6|*",'Danh sách test'!$P$5:$P$127,"Đã sửa – chờ test lại") -> 0 | H35: =COUNTIFS('Danh sách test'!$R$5:$R$127,"*|VD6|*",'Danh sách test'!$P$5:$P$127,"Chờ người / dữ liệu") -> 0 | I35: =IF(E35=0,"",IF(F35=E35,"Đạt",IF(G35>0,"Có lỗi",IF(H35>0,"Đang chờ",IF(F35>0,"Đang test","Chưa test"))))) -> Chưa test
A36: VD7 | B36: Lô còn 19 ngày | C36: Cảnh báo cận date | D36: Đạt 26/10 | E36: =COUNTIFS('Danh sách test'!$R$5:$R$127,"*|VD7|*") -> 2 | F36: =COUNTIFS('Danh sách test'!$R$5:$R$127,"*|VD7|*",'Danh sách test'!$P$5:$P$127,"Đạt") -> 0 | G36: =COUNTIFS('Danh sách test'!$R$5:$R$127,"*|VD7|*",'Danh sách test'!$P$5:$P$127,"Lỗi")+COUNTIFS('Danh sách test'!$R$5:$R$127,"*|VD7|*",'Danh sách test'!$P$5:$P$127,"Đã sửa – chờ test lại") -> 0 | H36: =COUNTIFS('Danh sách test'!$R$5:$R$127,"*|VD7|*",'Danh sách test'!$P$5:$P$127,"Chờ người / dữ liệu") -> 0 | I36: =IF(E36=0,"",IF(F36=E36,"Đạt",IF(G36>0,"Có lỗi",IF(H36>0,"Đang chờ",IF(F36>0,"Đang test","Chưa test"))))) -> Chưa test
A37: VD8 | B37: Bậc 3% | C37: Áp đúng 3% | D37: Đạt 26/10 | E37: =COUNTIFS('Danh sách test'!$R$5:$R$127,"*|VD8|*") -> 2 | F37: =COUNTIFS('Danh sách test'!$R$5:$R$127,"*|VD8|*",'Danh sách test'!$P$5:$P$127,"Đạt") -> 0 | G37: =COUNTIFS('Danh sách test'!$R$5:$R$127,"*|VD8|*",'Danh sách test'!$P$5:$P$127,"Lỗi")+COUNTIFS('Danh sách test'!$R$5:$R$127,"*|VD8|*",'Danh sách test'!$P$5:$P$127,"Đã sửa – chờ test lại") -> 0 | H37: =COUNTIFS('Danh sách test'!$R$5:$R$127,"*|VD8|*",'Danh sách test'!$P$5:$P$127,"Chờ người / dữ liệu") -> 0 | I37: =IF(E37=0,"",IF(F37=E37,"Đạt",IF(G37>0,"Có lỗi",IF(H37>0,"Đang chờ",IF(F37>0,"Đang test","Chưa test"))))) -> Chưa test
B39: 25 tình huống đã Đạt | C39: =COUNTIF(I5:I29,"Đạt")&" / 25" -> 0 / 25
B40: Ví dụ VD1–VD8 đã Đạt | C40: =COUNTIF(I30:I37,"Đạt")&" / 8" -> 0 / 8

Sheet Tiến độ
A1: TIẾN ĐỘ TEST — SỐ LIỆU BÁO CÁO
A2: Tự tính, không sửa tay. Copy bảng này khi báo cáo cuối ngày / cuối tuần.
A4: Phần | B4: Số mục | C4: Giờ ước tính | D4: Đạt | E4: Lỗi / chờ sửa | F4: Đang test | G4: Chưa test | H4: Đang chờ | I4: % mục đạt | J4: Giờ còn lại
A5: Chung & đăng nhập | B5: =COUNTIFS('Danh sách test'!$B$5:$B$127,$A5) -> 8 | C5: =SUMIFS('Danh sách test'!$I$5:$I$127,'Danh sách test'!$B$5:$B$127,$A5) -> 4.5 | D5: =COUNTIFS('Danh sách test'!$B$5:$B$127,$A5,'Danh sách test'!$P$5:$P$127,"Đạt") -> 0 | E5: =COUNTIFS('Danh sách test'!$B$5:$B$127,$A5,'Danh sách test'!$P$5:$P$127,"Lỗi")+COUNTIFS('Danh sách test'!$B$5:$B$127,$A5,'Danh sách test'!$P$5:$P$127,"Đã sửa – chờ test lại") -> 0 | F5: =COUNTIFS('Danh sách test'!$B$5:$B$127,$A5,'Danh sách test'!$P$5:$P$127,"Đang test") -> 0 | G5: =COUNTIFS('Danh sách test'!$B$5:$B$127,$A5,'Danh sách test'!$P$5:$P$127,"Chưa test") -> 8 | H5: =COUNTIFS('Danh sách test'!$B$5:$B$127,$A5,'Danh sách test'!$P$5:$P$127,"Chờ người / dữ liệu") -> 0 | I5: =IF(B5=0,0,D5/B5) -> 0 | J5: =C5-SUMIFS('Danh sách test'!$I$5:$I$127,'Danh sách test'!$B$5:$B$127,$A5,'Danh sách test'!$P$5:$P$127,"Đạt") -> 4.5
A6: Danh mục hàng & NCC | B6: =COUNTIFS('Danh sách test'!$B$5:$B$127,$A6) -> 14 | C6: =SUMIFS('Danh sách test'!$I$5:$I$127,'Danh sách test'!$B$5:$B$127,$A6) -> 10.25 | D6: =COUNTIFS('Danh sách test'!$B$5:$B$127,$A6,'Danh sách test'!$P$5:$P$127,"Đạt") -> 0 | E6: =COUNTIFS('Danh sách test'!$B$5:$B$127,$A6,'Danh sách test'!$P$5:$P$127,"Lỗi")+COUNTIFS('Danh sách test'!$B$5:$B$127,$A6,'Danh sách test'!$P$5:$P$127,"Đã sửa – chờ test lại") -> 0 | F6: =COUNTIFS('Danh sách test'!$B$5:$B$127,$A6,'Danh sách test'!$P$5:$P$127,"Đang test") -> 0 | G6: =COUNTIFS('Danh sách test'!$B$5:$B$127,$A6,'Danh sách test'!$P$5:$P$127,"Chưa test") -> 14 | H6: =COUNTIFS('Danh sách test'!$B$5:$B$127,$A6,'Danh sách test'!$P$5:$P$127,"Chờ người / dữ liệu") -> 0 | I6: =IF(B6=0,0,D6/B6) -> 0 | J6: =C6-SUMIFS('Danh sách test'!$I$5:$I$127,'Danh sách test'!$B$5:$B$127,$A6,'Danh sách test'!$P$5:$P$127,"Đạt") -> 10.25
A7: Chính sách & cài đặt | B7: =COUNTIFS('Danh sách test'!$B$5:$B$127,$A7) -> 14 | C7: =SUMIFS('Danh sách test'!$I$5:$I$127,'Danh sách test'!$B$5:$B$127,$A7) -> 10 | D7: =COUNTIFS('Danh sách test'!$B$5:$B$127,$A7,'Danh sách test'!$P$5:$P$127,"Đạt") -> 0 | E7: =COUNTIFS('Danh sách test'!$B$5:$B$127,$A7,'Danh sách test'!$P$5:$P$127,"Lỗi")+COUNTIFS('Danh sách test'!$B$5:$B$127,$A7,'Danh sách test'!$P$5:$P$127,"Đã sửa – chờ test lại") -> 0 | F7: =COUNTIFS('Danh sách test'!$B$5:$B$127,$A7,'Danh sách test'!$P$5:$P$127,"Đang test") -> 0 | G7: =COUNTIFS('Danh sách test'!$B$5:$B$127,$A7,'Danh sách test'!$P$5:$P$127,"Chưa test") -> 14 | H7: =COUNTIFS('Danh sách test'!$B$5:$B$127,$A7,'Danh sách test'!$P$5:$P$127,"Chờ người / dữ liệu") -> 0 | I7: =IF(B7=0,0,D7/B7) -> 0 | J7: =C7-SUMIFS('Danh sách test'!$I$5:$I$127,'Danh sách test'!$B$5:$B$127,$A7,'Danh sách test'!$P$5:$P$127,"Đạt") -> 10
A8: Chứng từ mua hàng (MH03) | B8: =COUNTIFS('Danh sách test'!$B$5:$B$127,$A8) -> 25 | C8: =SUMIFS('Danh sách test'!$I$5:$I$127,'Danh sách test'!$B$5:$B$127,$A8) -> 17.75 | D8: =COUNTIFS('Danh sách test'!$B$5:$B$127,$A8,'Danh sách test'!$P$5:$P$127,"Đạt") -> 0 | E8: =COUNTIFS('Danh sách test'!$B$5:$B$127,$A8,'Danh sách test'!$P$5:$P$127,"Lỗi")+COUNTIFS('Danh sách test'!$B$5:$B$127,$A8,'Danh sách test'!$P$5:$P$127,"Đã sửa – chờ test lại") -> 0 | F8: =COUNTIFS('Danh sách test'!$B$5:$B$127,$A8,'Danh sách test'!$P$5:$P$127,"Đang test") -> 0 | G8: =COUNTIFS('Danh sách test'!$B$5:$B$127,$A8,'Danh sách test'!$P$5:$P$127,"Chưa test") -> 24 | H8: =COUNTIFS('Danh sách test'!$B$5:$B$127,$A8,'Danh sách test'!$P$5:$P$127,"Chờ người / dữ liệu") -> 1 | I8: =IF(B8=0,0,D8/B8) -> 0 | J8: =C8-SUMIFS('Danh sách test'!$I$5:$I$127,'Danh sách test'!$B$5:$B$127,$A8,'Danh sách test'!$P$5:$P$127,"Đạt") -> 17.75
A9: Đặt hàng, hạn mức, công nợ | B9: =COUNTIFS('Danh sách test'!$B$5:$B$127,$A9) -> 7 | C9: =SUMIFS('Danh sách test'!$I$5:$I$127,'Danh sách test'!$B$5:$B$127,$A9) -> 4.5 | D9: =COUNTIFS('Danh sách test'!$B$5:$B$127,$A9,'Danh sách test'!$P$5:$P$127,"Đạt") -> 0 | E9: =COUNTIFS('Danh sách test'!$B$5:$B$127,$A9,'Danh sách test'!$P$5:$P$127,"Lỗi")+COUNTIFS('Danh sách test'!$B$5:$B$127,$A9,'Danh sách test'!$P$5:$P$127,"Đã sửa – chờ test lại") -> 0 | F9: =COUNTIFS('Danh sách test'!$B$5:$B$127,$A9,'Danh sách test'!$P$5:$P$127,"Đang test") -> 0 | G9: =COUNTIFS('Danh sách test'!$B$5:$B$127,$A9,'Danh sách test'!$P$5:$P$127,"Chưa test") -> 7 | H9: =COUNTIFS('Danh sách test'!$B$5:$B$127,$A9,'Danh sách test'!$P$5:$P$127,"Chờ người / dữ liệu") -> 0 | I9: =IF(B9=0,0,D9/B9) -> 0 | J9: =C9-SUMIFS('Danh sách test'!$I$5:$I$127,'Danh sách test'!$B$5:$B$127,$A9,'Danh sách test'!$P$5:$P$127,"Đạt") -> 4.5
A10: Thưởng, phân bổ, lô, quà, nhật ký | B10: =COUNTIFS('Danh sách test'!$B$5:$B$127,$A10) -> 9 | C10: =SUMIFS('Danh sách test'!$I$5:$I$127,'Danh sách test'!$B$5:$B$127,$A10) -> 5.5 | D10: =COUNTIFS('Danh sách test'!$B$5:$B$127,$A10,'Danh sách test'!$P$5:$P$127,"Đạt") -> 0 | E10: =COUNTIFS('Danh sách test'!$B$5:$B$127,$A10,'Danh sách test'!$P$5:$P$127,"Lỗi")+COUNTIFS('Danh sách test'!$B$5:$B$127,$A10,'Danh sách test'!$P$5:$P$127,"Đã sửa – chờ test lại") -> 0 | F10: =COUNTIFS('Danh sách test'!$B$5:$B$127,$A10,'Danh sách test'!$P$5:$P$127,"Đang test") -> 0 | G10: =COUNTIFS('Danh sách test'!$B$5:$B$127,$A10,'Danh sách test'!$P$5:$P$127,"Chưa test") -> 9 | H10: =COUNTIFS('Danh sách test'!$B$5:$B$127,$A10,'Danh sách test'!$P$5:$P$127,"Chờ người / dữ liệu") -> 0 | I10: =IF(B10=0,0,D10/B10) -> 0 | J10: =C10-SUMIFS('Danh sách test'!$I$5:$I$127,'Danh sách test'!$B$5:$B$127,$A10,'Danh sách test'!$P$5:$P$127,"Đạt") -> 5.5
A11: Báo cáo | B11: =COUNTIFS('Danh sách test'!$B$5:$B$127,$A11) -> 7 | C11: =SUMIFS('Danh sách test'!$I$5:$I$127,'Danh sách test'!$B$5:$B$127,$A11) -> 4 | D11: =COUNTIFS('Danh sách test'!$B$5:$B$127,$A11,'Danh sách test'!$P$5:$P$127,"Đạt") -> 0 | E11: =COUNTIFS('Danh sách test'!$B$5:$B$127,$A11,'Danh sách test'!$P$5:$P$127,"Lỗi")+COUNTIFS('Danh sách test'!$B$5:$B$127,$A11,'Danh sách test'!$P$5:$P$127,"Đã sửa – chờ test lại") -> 0 | F11: =COUNTIFS('Danh sách test'!$B$5:$B$127,$A11,'Danh sách test'!$P$5:$P$127,"Đang test") -> 0 | G11: =COUNTIFS('Danh sách test'!$B$5:$B$127,$A11,'Danh sách test'!$P$5:$P$127,"Chưa test") -> 7 | H11: =COUNTIFS('Danh sách test'!$B$5:$B$127,$A11,'Danh sách test'!$P$5:$P$127,"Chờ người / dữ liệu") -> 0 | I11: =IF(B11=0,0,D11/B11) -> 0 | J11: =C11-SUMIFS('Danh sách test'!$I$5:$I$127,'Danh sách test'!$B$5:$B$127,$A11,'Danh sách test'!$P$5:$P$127,"Đạt") -> 4
A12: 25 tình huống (chạy trọn) | B12: =COUNTIFS('Danh sách test'!$B$5:$B$127,$A12) -> 25 | C12: =SUMIFS('Danh sách test'!$I$5:$I$127,'Danh sách test'!$B$5:$B$127,$A12) -> 23 | D12: =COUNTIFS('Danh sách test'!$B$5:$B$127,$A12,'Danh sách test'!$P$5:$P$127,"Đạt") -> 0 | E12: =COUNTIFS('Danh sách test'!$B$5:$B$127,$A12,'Danh sách test'!$P$5:$P$127,"Lỗi")+COUNTIFS('Danh sách test'!$B$5:$B$127,$A12,'Danh sách test'!$P$5:$P$127,"Đã sửa – chờ test lại") -> 0 | F12: =COUNTIFS('Danh sách test'!$B$5:$B$127,$A12,'Danh sách test'!$P$5:$P$127,"Đang test") -> 0 | G12: =COUNTIFS('Danh sách test'!$B$5:$B$127,$A12,'Danh sách test'!$P$5:$P$127,"Chưa test") -> 21 | H12: =COUNTIFS('Danh sách test'!$B$5:$B$127,$A12,'Danh sách test'!$P$5:$P$127,"Chờ người / dữ liệu") -> 4 | I12: =IF(B12=0,0,D12/B12) -> 0 | J12: =C12-SUMIFS('Danh sách test'!$I$5:$I$127,'Danh sách test'!$B$5:$B$127,$A12,'Danh sách test'!$P$5:$P$127,"Đạt") -> 23
A13: Ví dụ bổ sung VD1–VD8 | B13: =COUNTIFS('Danh sách test'!$B$5:$B$127,$A13) -> 8 | C13: =SUMIFS('Danh sách test'!$I$5:$I$127,'Danh sách test'!$B$5:$B$127,$A13) -> 4.25 | D13: =COUNTIFS('Danh sách test'!$B$5:$B$127,$A13,'Danh sách test'!$P$5:$P$127,"Đạt") -> 0 | E13: =COUNTIFS('Danh sách test'!$B$5:$B$127,$A13,'Danh sách test'!$P$5:$P$127,"Lỗi")+COUNTIFS('Danh sách test'!$B$5:$B$127,$A13,'Danh sách test'!$P$5:$P$127,"Đã sửa – chờ test lại") -> 0 | F13: =COUNTIFS('Danh sách test'!$B$5:$B$127,$A13,'Danh sách test'!$P$5:$P$127,"Đang test") -> 0 | G13: =COUNTIFS('Danh sách test'!$B$5:$B$127,$A13,'Danh sách test'!$P$5:$P$127,"Chưa test") -> 7 | H13: =COUNTIFS('Danh sách test'!$B$5:$B$127,$A13,'Danh sách test'!$P$5:$P$127,"Chờ người / dữ liệu") -> 1 | I13: =IF(B13=0,0,D13/B13) -> 0 | J13: =C13-SUMIFS('Danh sách test'!$I$5:$I$127,'Danh sách test'!$B$5:$B$127,$A13,'Danh sách test'!$P$5:$P$127,"Đạt") -> 4.25
A14: Đối chiếu kế toán (chờ kế toán mới) | B14: =COUNTIFS('Danh sách test'!$B$5:$B$127,$A14) -> 6 | C14: =SUMIFS('Danh sách test'!$I$5:$I$127,'Danh sách test'!$B$5:$B$127,$A14) -> 19.5 | D14: =COUNTIFS('Danh sách test'!$B$5:$B$127,$A14,'Danh sách test'!$P$5:$P$127,"Đạt") -> 0 | E14: =COUNTIFS('Danh sách test'!$B$5:$B$127,$A14,'Danh sách test'!$P$5:$P$127,"Lỗi")+COUNTIFS('Danh sách test'!$B$5:$B$127,$A14,'Danh sách test'!$P$5:$P$127,"Đã sửa – chờ test lại") -> 0 | F14: =COUNTIFS('Danh sách test'!$B$5:$B$127,$A14,'Danh sách test'!$P$5:$P$127,"Đang test") -> 0 | G14: =COUNTIFS('Danh sách test'!$B$5:$B$127,$A14,'Danh sách test'!$P$5:$P$127,"Chưa test") -> 0 | H14: =COUNTIFS('Danh sách test'!$B$5:$B$127,$A14,'Danh sách test'!$P$5:$P$127,"Chờ người / dữ liệu") -> 6 | I14: =IF(B14=0,0,D14/B14) -> 0 | J14: =C14-SUMIFS('Danh sách test'!$I$5:$I$127,'Danh sách test'!$B$5:$B$127,$A14,'Danh sách test'!$P$5:$P$127,"Đạt") -> 19.5
A15: TỔNG | B15: =SUM(B5:B14) -> 123 | C15: =SUM(C5:C14) -> 103.25 | D15: =SUM(D5:D14) -> 0 | E15: =SUM(E5:E14) -> 0 | F15: =SUM(F5:F14) -> 0 | G15: =SUM(G5:G14) -> 111 | H15: =SUM(H5:H14) -> 12 | I15: =IF(B15=0,0,D15/B15) -> 0 | J15: =SUM(J5:J14) -> 103.25
A17: Câu trả lời nhanh cho sếp
A18: 25 tình huống kế toán gửi đã Đạt | C18: ='25 tình huống'!C39 -> 0 / 25
A19: Số mục test đã Đạt / tổng | C19: =D15&" / "&B15&" mục ("&TEXT(I15,"0%")&")" -> 0 / 123 mục (0%)
A20: Số mục đang lỗi / chờ sửa | C20: =E15 -> 0
A21: Số mục đang chờ người / dữ liệu | C21: =H15 -> 12
A23: Ước tính thời gian (1 tester)
A24: Giờ test vòng 1 — làm được ngay | C24: =SUMIFS('Danh sách test'!$I$5:$I$127,'Danh sách test'!$K$5:$K$127,"Không") -> 79.75
A25: Giờ test lại sau sửa lỗi | C25: =C24*'Hướng dẫn'!$C$8 -> 23.925
A26: Giờ các mục đang chờ (kế toán mới, file thật) | C26: =SUMIFS('Danh sách test'!$I$5:$I$127,'Danh sách test'!$K$5:$K$127,"Có") -> 23.5
A27: Số ngày làm việc — phần làm được ngay (vòng 1 + test lại) | C27: =ROUNDUP((C24+C25)/'Hướng dẫn'!$C$7,0) -> 18
A28: Ngày dự kiến xong phần làm được ngay | C28: =WORKDAY('Hướng dẫn'!$C$6,C27-1) -> 46345
A29: Số ngày thêm cho phần đang chờ (tính từ lúc có người / dữ liệu) | C29: =ROUNDUP(C26*(1+'Hướng dẫn'!$C$8)/'Hướng dẫn'!$C$7,0) -> 6
A30: Tổng số ngày làm việc nếu không phải chờ | C30: =C27+C29 -> 24
A31: Tổng số tuần (5 ngày / tuần) | C31: =ROUNDUP(C30/5,1) -> 4.8
A33: • Giả định: 1 tester đã được hướng dẫn qua phần mềm; số giờ mỗi ngày và tỷ lệ test lại sửa ở sheet Hướng dẫn.
A34: • Chưa tính thời gian dev sửa lỗi (phụ thuộc số lỗi tìm ra) — thường song song với test, nhưng lỗi lớn có thể làm chậm 1–2 ngày.
A35: • Phần "Đối chiếu kế toán" không bắt đầu được tới khi có kế toán mới làm cầu nối với phòng kế toán công ty tổng.
A36: • Phía bán (TH6, 7, 9, 10) hiện chỉ kiểm công thức; test thật khi làm phân hệ Bán hàng.

Sheet Chờ đợi
A1: VIỆC ĐANG CHỜ — CHƯA TEST ĐƯỢC
A2: Tự lấy các mục có "Đang chờ? = Có" ở sheet Danh sách test. Khi đã có người / dữ liệu: đổi ô đó thành "Không", mục tự xếp ngày.
A4: Mã test | B4: Phần | C4: Chức năng | D4: Đang chờ gì | E4: Giờ ước tính | F4: Trạng thái
A5: =IFERROR(INDEX('Danh sách test'!$A$5:$A$127,MATCH(1,'Danh sách test'!$S$5:$S$127,0)),"") -> CT-23 | B5: =IFERROR(INDEX('Danh sách test'!$B$5:$B$127,MATCH(1,'Danh sách test'!$S$5:$S$127,0)),"") -> Chứng từ mua hàng (MH03) | C5: =IFERROR(INDEX('Danh sách test'!$D$5:$D$127,MATCH(1,'Danh sách test'!$S$5:$S$127,0)),"") -> Nhập / xuất dòng hàng Excel | D5: =IFERROR(INDEX('Danh sách test'!$J$5:$J$127,MATCH(1,'Danh sách test'!$S$5:$S$127,0)),"") -> Chờ file Excel thật "VD1. Vinh Châu.xlsx" | E5: =IFERROR(INDEX('Danh sách test'!$I$5:$I$127,MATCH(1,'Danh sách test'!$S$5:$S$127,0)),"") -> 1 | F5: =IFERROR(INDEX('Danh sách test'!$P$5:$P$127,MATCH(1,'Danh sách test'!$S$5:$S$127,0)),"") -> Chờ người / dữ liệu
A6: =IFERROR(INDEX('Danh sách test'!$A$5:$A$127,MATCH(2,'Danh sách test'!$S$5:$S$127,0)),"") -> KB-06 | B6: =IFERROR(INDEX('Danh sách test'!$B$5:$B$127,MATCH(2,'Danh sách test'!$S$5:$S$127,0)),"") -> 25 tình huống (chạy trọn) | C6: =IFERROR(INDEX('Danh sách test'!$D$5:$D$127,MATCH(2,'Danh sách test'!$S$5:$S$127,0)),"") -> TH6 — Bán hàng có CK từng dòng (phía bán) | D6: =IFERROR(INDEX('Danh sách test'!$J$5:$J$127,MATCH(2,'Danh sách test'!$S$5:$S$127,0)),"") -> Phân hệ Bán hàng chưa làm — hiện chỉ kiểm công thức | E6: =IFERROR(INDEX('Danh sách test'!$I$5:$I$127,MATCH(2,'Danh sách test'!$S$5:$S$127,0)),"") -> 0.5 | F6: =IFERROR(INDEX('Danh sách test'!$P$5:$P$127,MATCH(2,'Danh sách test'!$S$5:$S$127,0)),"") -> Chờ người / dữ liệu
A7: =IFERROR(INDEX('Danh sách test'!$A$5:$A$127,MATCH(3,'Danh sách test'!$S$5:$S$127,0)),"") -> KB-07 | B7: =IFERROR(INDEX('Danh sách test'!$B$5:$B$127,MATCH(3,'Danh sách test'!$S$5:$S$127,0)),"") -> 25 tình huống (chạy trọn) | C7: =IFERROR(INDEX('Danh sách test'!$D$5:$D$127,MATCH(3,'Danh sách test'!$S$5:$S$127,0)),"") -> TH7 — Bậc CK số lượng (phía bán) | D7: =IFERROR(INDEX('Danh sách test'!$J$5:$J$127,MATCH(3,'Danh sách test'!$S$5:$S$127,0)),"") -> Phân hệ Bán hàng chưa làm — hiện chỉ kiểm công thức | E7: =IFERROR(INDEX('Danh sách test'!$I$5:$I$127,MATCH(3,'Danh sách test'!$S$5:$S$127,0)),"") -> 0.5 | F7: =IFERROR(INDEX('Danh sách test'!$P$5:$P$127,MATCH(3,'Danh sách test'!$S$5:$S$127,0)),"") -> Chờ người / dữ liệu
A8: =IFERROR(INDEX('Danh sách test'!$A$5:$A$127,MATCH(4,'Danh sách test'!$S$5:$S$127,0)),"") -> KB-09 | B8: =IFERROR(INDEX('Danh sách test'!$B$5:$B$127,MATCH(4,'Danh sách test'!$S$5:$S$127,0)),"") -> 25 tình huống (chạy trọn) | C8: =IFERROR(INDEX('Danh sách test'!$D$5:$D$127,MATCH(4,'Danh sách test'!$S$5:$S$127,0)),"") -> TH9 — CK + tặng hàng (phía bán) | D8: =IFERROR(INDEX('Danh sách test'!$J$5:$J$127,MATCH(4,'Danh sách test'!$S$5:$S$127,0)),"") -> Phân hệ Bán hàng chưa làm — hiện chỉ kiểm công thức | E8: =IFERROR(INDEX('Danh sách test'!$I$5:$I$127,MATCH(4,'Danh sách test'!$S$5:$S$127,0)),"") -> 0.5 | F8: =IFERROR(INDEX('Danh sách test'!$P$5:$P$127,MATCH(4,'Danh sách test'!$S$5:$S$127,0)),"") -> Chờ người / dữ liệu
A9: =IFERROR(INDEX('Danh sách test'!$A$5:$A$127,MATCH(5,'Danh sách test'!$S$5:$S$127,0)),"") -> KB-10 | B9: =IFERROR(INDEX('Danh sách test'!$B$5:$B$127,MATCH(5,'Danh sách test'!$S$5:$S$127,0)),"") -> 25 tình huống (chạy trọn) | C9: =IFERROR(INDEX('Danh sách test'!$D$5:$D$127,MATCH(5,'Danh sách test'!$S$5:$S$127,0)),"") -> TH10 — Đặt hàng có CK (phía bán) | D9: =IFERROR(INDEX('Danh sách test'!$J$5:$J$127,MATCH(5,'Danh sách test'!$S$5:$S$127,0)),"") -> Phân hệ Bán hàng chưa làm — hiện chỉ kiểm công thức | E9: =IFERROR(INDEX('Danh sách test'!$I$5:$I$127,MATCH(5,'Danh sách test'!$S$5:$S$127,0)),"") -> 0.5 | F9: =IFERROR(INDEX('Danh sách test'!$P$5:$P$127,MATCH(5,'Danh sách test'!$S$5:$S$127,0)),"") -> Chờ người / dữ liệu
A10: =IFERROR(INDEX('Danh sách test'!$A$5:$A$127,MATCH(6,'Danh sách test'!$S$5:$S$127,0)),"") -> VD-01 | B10: =IFERROR(INDEX('Danh sách test'!$B$5:$B$127,MATCH(6,'Danh sách test'!$S$5:$S$127,0)),"") -> Ví dụ bổ sung VD1–VD8 | C10: =IFERROR(INDEX('Danh sách test'!$D$5:$D$127,MATCH(6,'Danh sách test'!$S$5:$S$127,0)),"") -> VD1 — Nhập file Excel của NCC | D10: =IFERROR(INDEX('Danh sách test'!$J$5:$J$127,MATCH(6,'Danh sách test'!$S$5:$S$127,0)),"") -> Chờ file Excel thật | E10: =IFERROR(INDEX('Danh sách test'!$I$5:$I$127,MATCH(6,'Danh sách test'!$S$5:$S$127,0)),"") -> 1 | F10: =IFERROR(INDEX('Danh sách test'!$P$5:$P$127,MATCH(6,'Danh sách test'!$S$5:$S$127,0)),"") -> Chờ người / dữ liệu
